<?xml version="1.0" ?>
<!-- ===================================================================== -->
<!-- Before this URDF file was added to Drake, it was auto generated by
     `xacro` from a source file. While living in Drake, this URDF file 
     underwent changes and therefore cannot be exactly generated from the
     original source file. See pull requests #2163 and #2520.

     Collision models: complex meshes can drastically affect run time.
     Therefore some collision models are represented as simple cylinders
     instead of meshes. However it's important to have accurate collision
     models for the end of the arm because we anticipate that the end is the
     most likely part of the arm to make contact.
-->
<!-- ===================================================================== -->
<robot name="gripper" xmlns:xacro="http://www.ros.org/wiki/xacro">

<link
    name="base_link">
    <inertial>
      <origin
        xyz="0 0 0"
        rpy="1.57 0 0" />
      <mass
        value="0.3" />
      <inertia
        ixx="0.00028972"
        ixy="-5.7879E-10"
        ixz="-1.8543E-06"
        iyy="0.00030737"
        iyz="1.682E-12"
        izz="0.00019914" />
    </inertial>
    <visual>
      <origin
        xyz="0 0 0"
        rpy="1.57 0 0" />
      <geometry>
        <capsule radius="0.006" length=".06"/>
      </geometry>
      <material
        name="">
        <color
          rgba="0.1 0.1 0.1 1" />
      </material>
    </visual>
    <!-- <collision>
      <origin
        xyz="0 0 0"
        rpy="0 0 0" />
      <geometry>
        <mesh
          filename="meshes/robotiq_85_base_link_coarse.obj" />
      </geometry>
    </collision> -->
  </link>
  <link
    name="left_finger">
    <inertial>
      <origin
        xyz="0 0 0"
        rpy="0 0 0" />
      <mass
        value="0.05" />
      <inertia
        ixx="2.66832029033166E-07"
        ixy="1.66142314639824E-15"
        ixz="1.45945633322873E-07"
        iyy="1.3889233257419E-06"
        iyz="2.82951161241588E-15"
        izz="1.26603336914415E-06" />
    </inertial>
    <visual>
      <origin
        xyz="0 0 0"
        rpy="0 0 0" />
      <geometry>
        <capsule radius="0.005" length=".05"/>
      </geometry>
      <material
        name="">
        <color
          rgba="0.1 0.1 0.1 1" />
      </material>
    </visual>
  </link>

  <link
    name="right_finger">
    <inertial>
      <origin
        xyz="0 0 0"
        rpy="0 0 0" />
      <mass
        value="0.05" />
      <inertia
        ixx="2.66832029033166E-07"
        ixy="1.66142314639824E-15"
        ixz="1.45945633322873E-07"
        iyy="1.3889233257419E-06"
        iyz="2.82951161241588E-15"
        izz="1.26603336914415E-06" />
    </inertial>
    <visual>
      <origin
        xyz="0 0 0"
        rpy="0 0 0" />
      <geometry>
        <capsule radius="0.005" length=".05"/>
      </geometry>
      <material
        name="">
        <color
          rgba="0.1 0.1 0.1 1" />
      </material>
    </visual>
  </link>

  <joint
    name="base_joint"
    type="fixed">
    <origin
      xyz="0 0.03 0.025"
      rpy="0 0 0" />
    <parent
      link="base_link" />
    <child
      link="right_finger" />
  </joint>

  <joint
    name="gripper_joint"
    type="prismatic">
    <origin
      xyz="0 0 0"
      rpy="0 0 0" />
    <parent
      link="right_finger" />
    <child
      link="left_finger" />
    <axis
      xyz="0 -1 0" />
    <limit
      lower="0.01"
      upper="0.08"
      velocity="2.0"
      effort="100" />
  </joint>

  

</robot>